Workbook

Sheet Absences-Présences
G3: FR Absences/Présences Catalogue
A6: Absences/Présences EuHReka | C6: Used | D6: Paiement | G6: Retenue | J6: Pilotage Paie | V6: Customizing Table Y00BA_VIE_COMPAN
A7: Code Absences/Présences | B7: Libellé Absences | D7: Rubrique Paiement euHReka | E7: Libellé Rubrique paiement | F7: Unité de temps | G7: Rubrique Paiement euHReka | H7: Libellé Rubrique paiement | I7: Unité de temps | J7: Nombre | K7: Montant | L7: Unité de temps | M7: Formule de calcul | N7: Taux horaire | O7: Taux jour | P7: Pénalisant 13ème mois | Q7: Pénalisant Prime de Vacances | R7: Pénalisant Prime d'ancienneté | S7: Pénalisant RATP -> transport | T7: Additional Comments | U7: WD absence name | V7: Taux paiemnt | W7: Taux retenue | X7: Modicateur Eurheka | Y7: Valeur
A8: (01xx) | B8: Congés Payés
A9: 100 | B9: Congés payés acquis | C9: ■ | D9: 3750 | E9: Paiement CP acquis | F9: Jours de paie | G9: 3500 | H9: Retenue CP acquis | I9: Jours de paie | J9: ■ | K9: ■ | L9: Jour | M9: cf questionnaire de paie pour le 10èCP | O9: TJ10 | P9: □ | Q9: □ | R9: □ | S9: □ | T9: CP2 | U9: Vacation plan (Earned) - Congés payés acquis | V9: 07 | W9: 12 | X9: N/R | Y9: N/R
A10: 110 | B10: Congés payés anticipés | C10: ■ | D10: 3760 | E10: Paiement CP anticipés | F10: Jours de paie | G10: 3510 | H10: Retenue CP Anticipés | I10: Jours de paie | J10: ■ | K10: ■ | L10: Jour | M10: cf questionnaire de paie pour le 10èCP | O10: TJ10 | P10: □ | Q10: □ | R10: □ | S10: □ | T10: CP1 | U10: Vacation plan (In Progress) - Congés payés en-cours | V10: 11 | W10: 12 | X10: N/R | Y10: N/R
A11: 120 | B11: Congés payés reliquats | C11: ■ | D11: 3870 | E11: Paiement CP reliquats | F11: Jours de paie | G11: 3630 | H11: Retenue CP reliquats | I11: Jours de paie | J11: ■ | K11: ■ | L11: Jour | M11: cf questionnaire de paie pour le 10èCP | O11: TJ10 | P11: □ | Q11: □ | R11: □ | S11: □ | T11: CP3 | U11: Vacation plan (Earned) - Congés payés acquis - Carryover | V11: 09 | W11: 12 | X11: N/R | Y11: N/R
A12: 130 | B12: Congés de fractionnement | C12: □ | D12: 3790 | E12: Paiement Congés Fraction | F12: Jours de paie | G12: 3540 | H12: Retenue Congés Fraction | I12: Jours de paie | J12: ■ | K12: ■ | L12: Jour | M12: cf questionnaire de paie pour le 10èCP | O12: TJ6 | P12: □ | Q12: □ | R12: □ | S12: □ | V12: 30 | W12: 30 | X12: 06VL1 | Y12: =VLOOKUP(O12,'Taux de valorisation'!A:O,9,FALSE()) -> 12
A13: 140 | B13: Congés d'ancienneté | C13: ■ | D13: 3770 | E13: Paiement Congé d'ancienn. | F13: Jours de paie | G13: 3520 | H13: Retenue Congés d'Ancienn. | I13: Jours de paie | J13: ■ | K13: ■ | L13: Jour | M13: cf questionnaire de paie pour le 10èCP | O13: TJ10 | P13: □ | Q13: □ | R13: □ | S13: □ | U13: Seniority days | V13: 30 | W13: 30 | X13: 06VL1 | Y13: =VLOOKUP(O13,'Taux de valorisation'!A:O,9,FALSE()) -> 16
A14: 150 | B14: Congés cadres | C14: □ | D14: 3780 | E14: Paiement Congés Cadres | F14: Jours de paie | G14: 3530 | H14: Retenue Congés Cadres | I14: Jours de paie | J14: ■ | K14: ■ | L14: Jour | M14: cf questionnaire de paie pour le 10èCP | O14: TJ6 | P14: □ | Q14: □ | R14: □ | S14: □ | V14: 30 | W14: 30 | X14: 06VL1 | Y14: =VLOOKUP(O14,'Taux de valorisation'!A:O,9,FALSE()) -> 12
A15: 160 | B15: Congés conventionnels | C15: □ | D15: 3930 | E15: Paiem. Congés convent. | F15: Jours de paie | G15: 3690 | H15: Ret. Congés convention. | I15: Jours de paie | J15: □ | K15: □ | M15: cf questionnaire de paie pour le 10èCP | P15: □ | Q15: □ | R15: □ | S15: □ | V15: 30 | W15: 30 | X15: 06VL1 | Y15: =VLOOKUP(O15,'Taux de valorisation'!A:O,9,FALSE()) -> #N/A
A16: GAP with euHReka standard
A17: 161 | B17: Congés supplementaire | C17: ■ | D17: 3931 | E17: Paiem. Congés supplemen. | F17: Jours de paie | G17: 3691 | H17: Ret. Congés supplemen. | I17: Jours de paie | J17: ■ | K17: ■ | L17: Jour | O17: TJ10 | P17: □ | Q17: □ | R17: □ | S17: □ | U17: Extra Time vacation | X17: 06VL1 | Y17: =VLOOKUP(O17,'Taux de valorisation'!A:O,9,FALSE()) -> 16
A18: 162 | B18: Solidarite CP | C18: ■ | D18: 3932 | E18: Paiem.Solidarité CP | F18: Jours de paie | G18: 3692 | H18: Ret. Solidarité CP | I18: Jours de paie | J18: ■ | K18: ■ | L18: Jour | O18: TJ10 | P18: □ | Q18: □ | R18: □ | S18: □ | T18: pas de counter | U18: Solidarité to check | Y18: =VLOOKUP(O18,'Taux de valorisation'!A:O,10,FALSE()) -> 8
A19: 163 | B19: Solidarite | C19: ■ | D19: 3933 | E19: Paiem.Solidarité | F19: Jours de paie | G19: 3693 | H19: Retenue Solidarité | I19: Jours de paie | J19: ■ | K19: ■ | L19: Jour | O19: TJ10 | P19: □ | Q19: □ | R19: □ | S19: □ | T19: pas de counter | U19: Solidarité to check | X19: 06VL1 | Y19: =VLOOKUP(O19,'Taux de valorisation'!A:O,9,FALSE()) -> 16
C20: □ | J20: □ | K20: □ | P20: □ | Q20: □ | R20: □ | S20: □ | X20: 06VL1 | Y20: =VLOOKUP(O20,'Taux de valorisation'!A:O,9,FALSE()) -> #N/A
C21: □ | J21: □ | K21: □ | P21: □ | Q21: □ | R21: □ | S21: □ | X21: 06VL1 | Y21: =VLOOKUP(O21,'Taux de valorisation'!A:O,9,FALSE()) -> #N/A
A22: (04xx) | B22: 35h
A23: 400 | B23: RTT | C23: ■ | D23: 3800 | E23: Paiement RTT | F23: Jours de paie | G23: 3550 | H23: Retenue RTT | I23: Jours de paie | J23: ■ | K23: ■ | L23: Jour | O23: TJ10 | P23: □ | Q23: □ | R23: □ | S23: □ | U23: Work Time Reduction | V23: 31 | W23: 31 | X23: 06VL2 | Y23: =VLOOKUP(O23,'Taux de valorisation'!A:O,10,FALSE()) -> 8
A24: 410 | B24: RTT employé | C24: □ | D24: 3800 | E24: Paiement RTT | F24: Jours de paie | G24: 3550 | H24: Retenue RTT | I24: Jours de paie | J24: □ | K24: □ | L24: Jour | P24: □ | Q24: □ | R24: □ | S24: □ | V24: 31 | W24: 31 | X24: 06VL2 | Y24: =VLOOKUP(O24,'Taux de valorisation'!A:O,10,FALSE()) -> #N/A
A25: 420 | B25: RTT employeur | C25: □ | D25: 3800 | E25: Paiement RTT | F25: Jours de paie | G25: 3550 | H25: Retenue RTT | I25: Jours de paie | J25: □ | K25: □ | L25: Jour | P25: □ | Q25: □ | R25: □ | S25: □ | V25: 31 | W25: 31 | X25: 06VL2 | Y25: =VLOOKUP(O25,'Taux de valorisation'!A:O,10,FALSE()) -> #N/A
A26: 430 | B26: CET | C26: □ | D26: 3950 | E26: Paiement CET | F26: Jours de paie | G26: 3450 | H26: Retenue CET | I26: Jours de paie | J26: ■ | K26: ■ | L26: Jour | O26: TJ6 | P26: □ | Q26: □ | R26: □ | S26: □ | V26: 38 | W26: 31 | X26: 06VL2 | Y26: =VLOOKUP(O26,'Taux de valorisation'!A:O,10,FALSE()) -> 6
A27: GAP with euHReka standard
A28: 401 | B28: RTT solidarite | C28: ■ | D28: 3801 | E28: Paiem.Solidarité RTT | F28: Jours de paie | G28: 3551 | H28: Retenue Solidarité RTT | I28: Jours de paie | J28: ■ | K28: ■ | L28: Jour | O28: TJ10 | P28: □ | Q28: □ | R28: □ | S28: □ | T28: pas de counter | U28: Solidarité to check | V28: 31 | W28: 31 | X28: 06VL2 | Y28: =VLOOKUP(O28,'Taux de valorisation'!A:O,10,FALSE()) -> 8
C29: □ | J29: □ | K29: □ | P29: □ | Q29: □ | R29: □ | S29: □ | Y29: =VLOOKUP(O29,'Taux de valorisation'!A:O,10,FALSE()) -> #N/A
A30: (05xx) | B30: Repos Compensateur
A31: 500 | B31: Contrep. Oblig. Repos (H) | C31: □ | D31: 3810 | E31: Paiement Repos Comp Légal | F31: Heures de paie | G31: 3560 | H31: Retenue Repos Comp Légal | I31: Heures de paie | J31: ■ | K31: ■ | L31: Heure | N31: TH2 | P31: □ | Q31: □ | R31: □ | S31: ■ | V31: 32 | W31: 32 | X31: 06VL4 | Y31: =VLOOKUP(O31,'Taux de valorisation'!A:O,11,FALSE()) -> #N/A
A32: 510 | B32: Contrep. Oblig. Repos (J) | C32: □ | D32: 3D10 ?? | E32: Paiement Jour de Pont | F32: Jours de paie | G32: 3A10 ?? | H32: Retenue Jour de Pont | I32: Jours de paie | J32: □ | K32: □ | P32: □ | Q32: □ | R32: □ | S32: □ | X32: 06VL3 ?? | Y32: =VLOOKUP(O32,'Taux de valorisation'!A:O,12,FALSE()) -> #N/A
A33: 520 | B33: Repos compens. équivalent | C33: □ | D33: 3820 | E33: Paiem. Repos Comp Rempl | F33: Jours de paie | G33: 3570 | H33: Retenue Rep Comp Remplac | I33: Jours de paie | J33: □ | K33: □ | P33: □ | Q33: □ | R33: □ | S33: □ | V33: 33 | W33: 33 | X33: 06VL3 | Y33: =VLOOKUP(O33,'Taux de valorisation'!A:O,12,FALSE()) -> #N/A
A34: 530 | B34: Repos compens. modulation | C34: □ | D34: 3830 | E34: Paiem. Repos Comp. Modul. | F34: Jours de paie | G34: 3580 | H34: Retenue Rep Comp Modul | I34: Jours de paie | J34: □ | K34: □ | P34: □ | Q34: □ | R34: □ | S34: □ | V34: 33 | W34: 33 | X34: 06VL3 | Y34: =VLOOKUP(O34,'Taux de valorisation'!A:O,12,FALSE()) -> #N/A
A35: 540 | B35: Recup crédit d'heures J | C35: □ | D35: 3840 | E35: Paiement Crédit d'Heures | F35: Jours de paie | G35: 3590 | H35: Retenue Crédit d'heures | I35: Jours de paie | J35: □ | K35: □ | P35: □ | Q35: □ | R35: □ | S35: □ | V35: 33 | W35: 33 | X35: 06VL3 | Y35: =VLOOKUP(O35,'Taux de valorisation'!A:O,12,FALSE()) -> #N/A
A36: GAP with euHReka standard
C37: □ | J37: □ | K37: □ | O37: TJ6 | P37: □ | Q37: □ | R37: □ | S37: ■ | Y37: =VLOOKUP(O37,'Taux de valorisation'!A:O,12,FALSE()) -> N/R
C38: □ | J38: □ | K38: □ | O38: TJ6 | P38: □ | Q38: □ | R38: □ | S38: □ | Y38: =VLOOKUP(O38,'Taux de valorisation'!A:O,12,FALSE()) -> N/R
C39: □ | J39: □ | K39: □ | O39: TJ6 | P39: □ | Q39: □ | R39: □ | S39: □ | Y39: =VLOOKUP(O39,'Taux de valorisation'!A:O,12,FALSE()) -> N/R
C40: □ | J40: □ | K40: □ | P40: □ | Q40: □ | R40: □ | S40: □ | Y40: =VLOOKUP(O40,'Taux de valorisation'!A:O,12,FALSE()) -> #N/A
A41: (1xxx et 2xxx) | B41: Arrêt de travail
A42: 1100 | B42: Maladie | C42: ■ | D42: 3200 | E42: Paiement Maladie 100% | F42: Jours calendrier | G42: 3000 | H42: Retenue Maladie | I42: Jours calendrier | J42: ■ | K42: ■ | L42: Jour | O42: TJ17 | P42: □ | Q42: □ | R42: □ | S42: ■ | T42: Pénalise RATP si absence tout le mois | U42: Sick Time Off | V42: 34 | W42: 34 | X42: 06VL5 | Y42: =VLOOKUP(O42,'Taux de valorisation'!A:O,13,FALSE()) -> 1
A43: 1100 | B43: Maladie | C43: □ | D43: 3360 | E43: Paiement Maladie 90% | F43: Jours calendrier | G43: 3000 | H43: Retenue Maladie | I43: Jours calendrier | J43: □ | K43: □ | P43: □ | Q43: □ | R43: □ | S43: □ | V43: 34 | W43: 34 | X43: 06VL5 | Y43: =VLOOKUP(O43,'Taux de valorisation'!A:O,13,FALSE()) -> #N/A
A44: 1100 | B44: Maladie | C44: □ | D44: 3210 | E44: Paiement Maladie 75% | F44: Jours calendrier | G44: 3000 | H44: Retenue Maladie | I44: Jours calendrier | J44: □ | K44: □ | P44: □ | Q44: □ | R44: □ | S44: □ | V44: 34 | W44: 34 | X44: 06VL5 | Y44: =VLOOKUP(O44,'Taux de valorisation'!A:O,13,FALSE()) -> #N/A
...

Sheet Parameter
A1: Please do not change !
A3: Tax | B3: Regular tax
B4: Exceptional tax
A6: Freq | B6: Automatic
B7: Recurring
B8: Ad-hoc
A10: Sign | B10: Payment
B11: Deduction
A13: Char | B13: Amount
B14: Number
B15: Both
A17: Dec | B17: Yes
B18: No
A21: AcType | B21: C - Expense account (C with EG)
B22: D - Expense account (C w/o EG)
B23: A - Balance sheet account (F with EG)
B24: B - Balance sheet account (F w/o EG)
B25: E - Balance sheet acc with perno (Q with EG)
B26: F - Balance sheet acc with perno (Q w/o EG)
B27: G - Personal customer accounts (D with EG)
B28: H - Personal customer accounts (D w/o EG)
B29: I - Personal vendor accounts (K with EG)
B30: J - Personal vendor accounts (K w/o EG)
B31: K - Check RA balance (FL with EG)
B32: L - Check RA balance (FL w/o EG)
B33: M - Balance sheet acc orig perno only (FO with EG)
... B42: Z - Expense account w/o quantity (CN w/o EG)
A53: /102 | B53: Reg
A54: /103 | B54: Non-Per
A55: /112 | B55: Pen. Reg
A56: N | B56: N
A57: PC47 | B57: Lump Sum
A58: - | B58: -
A70: /152 | B70: Reg
A71: /153 | B71: Non-Per
A72: /158 | B72: Reg Comm.
A73: /162 | B73: Pen. Reg
A74: N | B74: N
A75: PC47 | B75: Lump Sum
... A123: * | B123: *

Sheet Taux de valorisation
A1: Code | B1: Libellé | C1: Taux euHReka | D1: Formule | G1: Rubriques de PY | H1: Waggetype Class =01 | I1: Modif char 06VL1 | J1: Modif char 06VL2 | K1: Modif char 06VL3 | L1: Modif char 06VL4 | M1: Modif char 06VL5 | N1: Modif char 06VL6 | O1: Modif char 06VL7
A2: TH1 | B2: Taux horaire de base | C2: /001 | D2: Salaire de Base / horaire mensuel du salarié | E2: overtim | F2: Primes de fonction | H2: CL01 -> Value = 2 | I2: N/R | J2: N/R | K2: N/R | L2: 1 | M2: 4 | N2: 11 | O2: 11
A3: TH2 | B3: Taux horaire de base + PA | C3: /003 | D3: (Salaire de Base + Prime Ancienneté) / horaire mensuel du salarié | H3: CL01 -> Value = 2 | I3: N/R | J3: N/R | K3: N/R | L3: 2 | M3: 5 | N3: 12 | O3: 12
A4: TH3 | B4: Taux horaire de base + PA + Primes | C4: /004 | D4: (Salaire de Base + Prime Ancienneté + Prime de Fonction) / horaire mensuel du salarié | H4: CL01 -> Value = 2 | I4: N/R | J4: N/R | K4: N/R | L4: 3 | M4: 6 | N4: 13 | O4: 13
A5: TJ1 | B5: Taux jour ouvré Base | C5: /074 | D5: Salaire de Base / Nb de jours ouvrés | H5: CL01 -> Value = 2 | I5: 7 | J5: 4 | K5: 4 | L5: N/R | M5: N/R | N5: 4 | O5: 4
A6: TJ2 | B6: Taux jour fixe 30 jours Base | C6: /075 | D6: Salaire de Base / Constante 30 | H6: CL01 -> Value = 2 | I6: 8 | J6: NS | K6: NS | L6: N/R | M6: N/R | N6: NS | O6: NS
A7: TJ3 | B7: Taux jour fixe 24 jours Base | C7: /076 | D7: Salaire de Base / Constante 24 | H7: CL01 -> Value = 2 | I7: 9 | J7: NS | K7: NS | L7: N/R | M7: N/R | N7: NS | O7: NS
A8: TJ4 | B8: Taux jour 21,66 jours Base | C8: /077 | D8: Salaire de Base / Constante 21,66 | H8: CL01 -> Value = 2 | I8: 10 | J8: 5 | K8: 5 | L8: N/R | M8: N/R | N8: 5 | O8: 5
A9: TJ5 | B9: Taux jour calendaire Base | C9: /078 | D9: Salaire de Base / Nombre de jours calendaires | H9: CL01 -> Value = 2 | I9: 11 | J9: NS | K9: NS | L9: N/R | M9: 2 | N9: NS | O9: NS
A10: TJ6 | B10: Taux jour fixe 22 jours Base | C10: /079 | D10: Salaire de Base / Constante 22 | I10: 12 | J10: 6 | K10: 6 | L10: N/R | M10: N/R | N10: 6 | O10: 6
A11: TJ7 | B11: Taux jour ouvré Base + PA | C11: /084 | D11: (Salaire de Base + Prime Ancienneté) / Nb de jours ouvrés | I11: 13 | J11: 7 | K11: 7 | L11: N/R | M11: N/R | N11: 7 | O11: 7
A12: TJ8 | B12: Taux jour fixe 30 jours Base + PA | C12: /085 | D12: (Salaire de Base + Prime Ancienneté) / Constante 30 | I12: 14 | J12: NS | K12: NS | L12: N/R | M12: N/R | N12: NS | O12: NS
A13: TJ9 | B13: Taux jour fixe 24 jours Base + PA | C13: /086 | D13: (Salaire de Base + Prime Ancienneté) / Constante 24 | I13: 15 | J13: NS | K13: NS | L13: N/R | M13: N/R | N13: NS | O13: NS
A14: TJ10 | B14: Taux jour 21,66 jours Base + PA | C14: /087 | D14: (Salaire de Base + Prime Ancienneté) / Constante 21,66 | I14: 16 | J14: 8 | K14: 8 | L14: N/R | M14: N/R | N14: 8 | O14: 8
A15: TJ11 | B15: Taux jour calendaire Base + PA | C15: /088 | D15: (Salaire de Base + Prime Ancienneté) / Nombre de jours calendaires | I15: 17 | J15: 10 | K15: 10 | L15: N/R | M15: 3 | N15: 10 | O15: 10
A16: TJ12 | B16: Taux jour fixe 22 jours Base + PA | C16: /089 | D16: (Salaire de Base + Prime Ancienneté) / Constante 22 | I16: 18 | J16: 9 | K16: 9 | L16: N/R | M16: N/R | N16: 9 | O16: 9
A17: TJ13 | B17: Taux jour ouvré Base + PA + Primes | C17: /002 | D17: (Salaire de Base + Prime Ancienneté + Prime de Fonction) / Nb de jours ouvrés | I17: 1 | J17: 1 | K17: 1 | L17: N/R | M17: N/R | N17: 1 | O17: 1
A18: TJ14 | B18: Taux jour fixe 30 jours Base + PA + Primes | C18: /095 | D18: (Salaire de Base + Prime Ancienneté + Prime de Fonction) / Constante 30 | I18: 2 | J18: NS | K18: NS | L18: N/R | M18: N/R | N18: NS | O18: NS
A19: TJ15 | B19: Taux jour fixe 24 jours Base + PA + Primes | C19: /096 | D19: (Salaire de Base + Prime Ancienneté + Prime de Fonction) / Constante 24 | I19: 3 | J19: NS | K19: NS | L19: N/R | M19: N/R | N19: NS | O19: NS
A20: TJ16 | B20: Taux jour 21,66 jours Base + PA + Primes | C20: /097 | D20: (Salaire de Base + Prime Ancienneté + Prime de Fonction) / Constante 21,66 | I20: 4 | J20: 2 | K20: 2 | L20: N/R | M20: N/R | N20: 2 | O20: 2
A21: TJ17 | B21: Taux jour calendaire Base + PA + Primes | C21: /098 | D21: (Salaire de Base + Prime Ancienneté + Prime de Fonction) / Nombre de jours calendaires | I21: 5 | J21: NS | K21: NS | L21: N/R | M21: 1 | N21: NS | O21: NS
A22: TJ18 | B22: Taux jour fixe 22 jours Base + PA + Primes | C22: /099 | D22: (Salaire de Base + Prime Ancienneté + Prime de Fonction) / Constante 22 | I22: 6 | J22: 3 | K22: 3 | L22: N/R | M22: N/R | N22: 3 | O22: 3
A23: GAP with euHReka standard
D32: Entrées spécifiques

Sheet Calendrier
A1: Code | B1: Désignation
A2: AI | B2: Absence injustifiée
A3: AJ | B3: Accident de trajet
A4: AN | B4: Absence aut. non pay
A5: AP | B5: Absence aut. payée
A6: AT | B6: AT
A7: CA | B7: Congé d'adoption
A8: CC | B8: Congé création d’ent
A9: CH | B9: Chômage partiel
A10: CP | B10: Congé Payé
A11: CS | B11: Congé sabbatique
A12: CT | B12: Chômage technique
... A31: TT | B31: Mi-temps thérapeutiq
E34: Entrées spécifiques

Sheet Sheet1
A1: 3550 | B1: Retenue RTT
A2: 3550 | B2: Retenue RTT
A3: 3550 | B3: Retenue RTT
A4: 3450 | B4: Retenue CET

Sheet Aide remplissage
A7: Absences/Présences Catalogue
A10: Le but de cet Excel est de documenter toutes les absences/présences nécessaire pour couvrir vos besoins.
B13: Categorie | C13: Titre colonne | D13: Description de chaque colonne
B14: Absences/Présences EuHReka | C14: Code Absences/Présences | D14: C'est le code utilisé dans euHReka. 4 caractères max.
C15: Libellé Absences | D15: Description de l'absence. 25 caractères max.
B16: Paiement | C16: Rubrique Paiement euHReka | D16: Code rubrique euHReka. 4 caractères max.
C17: Libellé Rubrique paiement | D17: Description rubrique euHReka. 25 caractères max.
C18: Unité de temps | D18: Il existe 5 unités de temps pour mesurer la durée d'une absence : - Jours calendrier - Jours d'absence - Heures d'absence - Jours de paie - Heures de paie
B19: Retenue | C19: Rubrique Retenue euHReka | D19: Code rubrique euHReka. 4 caractères max.
C20: Libellé Rubrique Retenue | D20: Description rubrique euHReka. 25 caractères max.
C21: Unité de temps | D21: Il existe 5 unités de temps pour mesurer la durée d'une absence : - Jours calendrier - Jours d'absence - Heures d'absence - Jours de paie - Heures de paie
B22: Pilotage Paie | C22: Nombre | D22: Affichage du nombre d'heure/jour sur le bulletin
C23: Montant | D23: Affichage du montant sur le bulletin
C24: Unité de temps | D24: L'absence est valorisée en heure ou en Jour
C25: Taux horaire | D25: Taux de valorisation (voir Onglet Taux de valorisation).
C26: Taux jour
C27: Pénalisant 13ème mois | D27: Se reporter à la section 5.5.3 du quesionnaire de paie
C28: Pénalisant Prime de Vacance | D28: Se reporter à la section 5.6.4 du quesionnaire de paie
B29: Pilotage Post-Paie | C29: Affichage Bulletin | D29: Affichage de l'absence sur le bulletin de salaire du salarié en dessous de la partie Brute
C30: Affichage Calendrier Bulletin | D30: Affichage du code d'absence dans le calendrier du bulletin de salaire. Pour plus d'information, se reporter à la section 10.1.1.3 du quesitonnaire de paie
C31: Posting FI | D31: Les rubriques de paiement/retenue doivent être postées en Finance | Z31: Automatic
A49: ■
A50: □
